Traceback (most recent call last):
  File "/opt/hostedtoolcache/Python/3.9.21/x64/lib/python3.9/site-packages/jupyter_cache/executors/utils.py", line 58, in single_nb_execution
    executenb(
  File "/opt/hostedtoolcache/Python/3.9.21/x64/lib/python3.9/site-packages/nbclient/client.py", line 1319, in execute
    return NotebookClient(nb=nb, resources=resources, km=km, **kwargs).execute()
  File "/opt/hostedtoolcache/Python/3.9.21/x64/lib/python3.9/site-packages/jupyter_core/utils/__init__.py", line 165, in wrapped
    return loop.run_until_complete(inner)
  File "/opt/hostedtoolcache/Python/3.9.21/x64/lib/python3.9/asyncio/base_events.py", line 647, in run_until_complete
    return future.result()
  File "/opt/hostedtoolcache/Python/3.9.21/x64/lib/python3.9/site-packages/nbclient/client.py", line 709, in async_execute
    await self.async_execute_cell(
  File "/opt/hostedtoolcache/Python/3.9.21/x64/lib/python3.9/site-packages/nbclient/client.py", line 1062, in async_execute_cell
    await self._check_raise_for_error(cell, cell_index, exec_reply)
  File "/opt/hostedtoolcache/Python/3.9.21/x64/lib/python3.9/site-packages/nbclient/client.py", line 918, in _check_raise_for_error
    raise CellExecutionError.from_cell_and_msg(cell, exec_reply_content)
nbclient.exceptions.CellExecutionError: An error occurred while executing the following cell:
------------------
def convert_docx_to_md_with_images(docx_path, output_md, images_folder):
    """
    Konvertierung von .docx Datei zu Markdown und extrahiert die Bilder automatisch in einen Ordner.
    """
    # Ensure the images folder exists
    if not os.path.exists(images_folder):
        os.makedirs(images_folder)

    # Use Pandoc for text conversion with image extraction
    pandoc_command = [
        "pandoc",
        docx_path,
        "-f", "docx",
        "-t", "gfm",  # GitHub-Flavored Markdown for cleaner tables
        "--wrap=none",
        f"--extract-media={images_folder}",  # Extract media to the specified folder
        "-o", output_md
    ]
    
    try:
        subprocess.run(pandoc_command, check=True)
        print(f"Conversion completed. Markdown saved to {output_md}. Images saved to {images_folder}.")
    except subprocess.CalledProcessError as e:
        print(f"Error during conversion: {e}")

# Example usage
docx_path = "Sample_Academic_Document.docx"  # Path to the input Word document
output_md = "Sample_Markdown.md"  # Path to the output Markdown file
images_folder = "images"  # Folder to store extracted images

convert_docx_to_md_with_images(docx_path, output_md, images_folder)

------------------


[0;31m---------------------------------------------------------------------------[0m
[0;31mFileNotFoundError[0m                         Traceback (most recent call last)
Cell [0;32mIn[2], line 31[0m
[1;32m     28[0m output_md [38;5;241m=[39m [38;5;124m"[39m[38;5;124mSample_Markdown.md[39m[38;5;124m"[39m  [38;5;66;03m# Path to the output Markdown file[39;00m
[1;32m     29[0m images_folder [38;5;241m=[39m [38;5;124m"[39m[38;5;124mimages[39m[38;5;124m"[39m  [38;5;66;03m# Folder to store extracted images[39;00m
[0;32m---> 31[0m [43mconvert_docx_to_md_with_images[49m[43m([49m[43mdocx_path[49m[43m,[49m[43m [49m[43moutput_md[49m[43m,[49m[43m [49m[43mimages_folder[49m[43m)[49m

Cell [0;32mIn[2], line 21[0m, in [0;36mconvert_docx_to_md_with_images[0;34m(docx_path, output_md, images_folder)[0m
[1;32m     10[0m pandoc_command [38;5;241m=[39m [
[1;32m     11[0m     [38;5;124m"[39m[38;5;124mpandoc[39m[38;5;124m"[39m,
[1;32m     12[0m     docx_path,
[0;32m   (...)[0m
[1;32m     17[0m     [38;5;124m"[39m[38;5;124m-o[39m[38;5;124m"[39m, output_md
[1;32m     18[0m ]
[1;32m     20[0m [38;5;28;01mtry[39;00m:
[0;32m---> 21[0m     [43msubprocess[49m[38;5;241;43m.[39;49m[43mrun[49m[43m([49m[43mpandoc_command[49m[43m,[49m[43m [49m[43mcheck[49m[38;5;241;43m=[39;49m[38;5;28;43;01mTrue[39;49;00m[43m)[49m
[1;32m     22[0m     [38;5;28mprint[39m([38;5;124mf[39m[38;5;124m"[39m[38;5;124mConversion completed. Markdown saved to [39m[38;5;132;01m{[39;00moutput_md[38;5;132;01m}[39;00m[38;5;124m. Images saved to [39m[38;5;132;01m{[39;00mimages_folder[38;5;132;01m}[39;00m[38;5;124m.[39m[38;5;124m"[39m)
[1;32m     23[0m [38;5;28;01mexcept[39;00m subprocess[38;5;241m.[39mCalledProcessError [38;5;28;01mas[39;00m e:

File [0;32m/opt/hostedtoolcache/Python/3.9.21/x64/lib/python3.9/subprocess.py:505[0m, in [0;36mrun[0;34m(input, capture_output, timeout, check, *popenargs, **kwargs)[0m
[1;32m    502[0m     kwargs[[38;5;124m'[39m[38;5;124mstdout[39m[38;5;124m'[39m] [38;5;241m=[39m PIPE
[1;32m    503[0m     kwargs[[38;5;124m'[39m[38;5;124mstderr[39m[38;5;124m'[39m] [38;5;241m=[39m PIPE
[0;32m--> 505[0m [38;5;28;01mwith[39;00m [43mPopen[49m[43m([49m[38;5;241;43m*[39;49m[43mpopenargs[49m[43m,[49m[43m [49m[38;5;241;43m*[39;49m[38;5;241;43m*[39;49m[43mkwargs[49m[43m)[49m [38;5;28;01mas[39;00m process:
[1;32m    506[0m     [38;5;28;01mtry[39;00m:
[1;32m    507[0m         stdout, stderr [38;5;241m=[39m process[38;5;241m.[39mcommunicate([38;5;28minput[39m, timeout[38;5;241m=[39mtimeout)

File [0;32m/opt/hostedtoolcache/Python/3.9.21/x64/lib/python3.9/subprocess.py:951[0m, in [0;36mPopen.__init__[0;34m(self, args, bufsize, executable, stdin, stdout, stderr, preexec_fn, close_fds, shell, cwd, env, universal_newlines, startupinfo, creationflags, restore_signals, start_new_session, pass_fds, user, group, extra_groups, encoding, errors, text, umask)[0m
[1;32m    947[0m         [38;5;28;01mif[39;00m [38;5;28mself[39m[38;5;241m.[39mtext_mode:
[1;32m    948[0m             [38;5;28mself[39m[38;5;241m.[39mstderr [38;5;241m=[39m io[38;5;241m.[39mTextIOWrapper([38;5;28mself[39m[38;5;241m.[39mstderr,
[1;32m    949[0m                     encoding[38;5;241m=[39mencoding, errors[38;5;241m=[39merrors)
[0;32m--> 951[0m     [38;5;28;43mself[39;49m[38;5;241;43m.[39;49m[43m_execute_child[49m[43m([49m[43margs[49m[43m,[49m[43m [49m[43mexecutable[49m[43m,[49m[43m [49m[43mpreexec_fn[49m[43m,[49m[43m [49m[43mclose_fds[49m[43m,[49m
[1;32m    952[0m [43m                        [49m[43mpass_fds[49m[43m,[49m[43m [49m[43mcwd[49m[43m,[49m[43m [49m[43menv[49m[43m,[49m
[1;32m    953[0m [43m                        [49m[43mstartupinfo[49m[43m,[49m[43m [49m[43mcreationflags[49m[43m,[49m[43m [49m[43mshell[49m[43m,[49m
[1;32m    954[0m [43m                        [49m[43mp2cread[49m[43m,[49m[43m [49m[43mp2cwrite[49m[43m,[49m
[1;32m    955[0m [43m                        [49m[43mc2pread[49m[43m,[49m[43m [49m[43mc2pwrite[49m[43m,[49m
[1;32m    956[0m [43m                        [49m[43merrread[49m[43m,[49m[43m [49m[43merrwrite[49m[43m,[49m
[1;32m    957[0m [43m                        [49m[43mrestore_signals[49m[43m,[49m
[1;32m    958[0m [43m                        [49m[43mgid[49m[43m,[49m[43m [49m[43mgids[49m[43m,[49m[43m [49m[43muid[49m[43m,[49m[43m [49m[43mumask[49m[43m,[49m
[1;32m    959[0m [43m                        [49m[43mstart_new_session[49m[43m)[49m
[1;32m    960[0m [38;5;28;01mexcept[39;00m:
[1;32m    961[0m     [38;5;66;03m# Cleanup if the child failed starting.[39;00m
[1;32m    962[0m     [38;5;28;01mfor[39;00m f [38;5;129;01min[39;00m [38;5;28mfilter[39m([38;5;28;01mNone[39;00m, ([38;5;28mself[39m[38;5;241m.[39mstdin, [38;5;28mself[39m[38;5;241m.[39mstdout, [38;5;28mself[39m[38;5;241m.[39mstderr)):

File [0;32m/opt/hostedtoolcache/Python/3.9.21/x64/lib/python3.9/subprocess.py:1837[0m, in [0;36mPopen._execute_child[0;34m(self, args, executable, preexec_fn, close_fds, pass_fds, cwd, env, startupinfo, creationflags, shell, p2cread, p2cwrite, c2pread, c2pwrite, errread, errwrite, restore_signals, gid, gids, uid, umask, start_new_session)[0m
[1;32m   1835[0m     [38;5;28;01mif[39;00m errno_num [38;5;241m!=[39m [38;5;241m0[39m:
[1;32m   1836[0m         err_msg [38;5;241m=[39m os[38;5;241m.[39mstrerror(errno_num)
[0;32m-> 1837[0m     [38;5;28;01mraise[39;00m child_exception_type(errno_num, err_msg, err_filename)
[1;32m   1838[0m [38;5;28;01mraise[39;00m child_exception_type(err_msg)

[0;31mFileNotFoundError[0m: [Errno 2] No such file or directory: 'pandoc'

